Workbook

Sheet Cover
B3: Elan1 Govern · Series A Financial Model
B5: The governance platform for AI agents — it decides before every tool call, makes a named person approve the risky ones, refuses what it must, and produces the proof
B7: Prepared for Series A investors · Plan period October 2026 to March 2031 · 22 September 2026, revised 27 October 2026 · Strictly confidential
B9: Revised edition 27 October 2026 — see Revision log
B11: THE ASK
B12: Series A round | C12: Rs 180.0 crore / US$20.0 million, in three tranches against gates
B13: Founder and angel bridge | C13: Rs 8.0 crore, October 2026 — precedes the round and is not part of the Rs 180 crore
B14: Tranche 1 — close | C14: Rs 63.0 crore, March 2027
B15: Tranche 2 — Gate A | C15: Rs 72.0 crore, October 2028
B16: Tranche 3 — Gate B | C16: Rs 45.0 crore, July 2029
B17: Minimum cash on the plan | C17: Rs 4.4 crore, February 2027 — the month before tranche 1 closes
B19: CURRENCY CONVENTION
B20: Reporting currency | C20: Indian rupees. 1 crore = 10,000,000; 1 lakh = 100,000
B21: US dollar view | C21: Rs 90.00 = US$1.00 throughout. Rs crore ÷ 9 = US$ million
B22: Units | C22: Figures are in Rs crore unless the sheet states otherwise
B24: HOW THIS WORKBOOK IS BUILT
B25: One 54-month engine drives every number. Months run October 2026 to March 2031.
B26: The monthly, quarterly and annual views on the sheets that follow are aggregations of that single engine,
B27: so monthly, quarterly and annual figures tie to the rupee by construction — nothing is entered twice.
B28: Engine outputs are hardcoded. Derived lines — gross profit, margins, totals, percentages of revenue and the
B29: opening-to-closing cash chain — are live Excel formulas, so a reader can trace and re-run the arithmetic.
B30: Refusals are metered at quantity zero and are never billed. Prices are flat to March 2029, then 4% p.a.
B32: TAB INDEX
B33: Sheet | C33: What it shows
B34: Assumptions | C34: Every driver and price in one place — price book, ramps, bands, funding schedule
B35: Summary P&L | C35: Five financial years: revenue to EBIT, exit ARR, cash, headcount, tenants; US$ block
B36: Monthly FY2026-27 | C36: October 2026 to March 2027 month by month in Rs lakh, plus headcount by function
B37: Quarterly FY2027-28 | C37: The four FY2027-28 quarters in detail, then all 18 quarters of the plan
B38: Annual FY2028-31 | C38: The three scale years in full: P&L, revenue and opex by line, people, customers
B39: Revenue build | C39: Every revenue line by year and by quarter, with the channel contra and the mix
B40: Cost build | C40: COGS split and every operating cost line by year, with percentage of revenue
B41: Headcount | C41: All ten functions by month for 54 months, year-end bands and the people-cost bridge
B42: Unit economics | C42: Governed action volumes, revenue and cost per action, and the price anchors
B43: Cash and funding | C43: 54-month cash chain: opening, EBITDA, capex, working capital, funding, closing
B44: Scenarios | C44: Base, downside and upside side by side, with the scenario definitions
B45: Gate calendar | C45: The dated events that release tranches and turn on revenue lines
B47: All figures generated 22 September 2026 from the elan1 Series A engine. Do not alter engine outputs without re-running the model.
B49: Revised 27 October 2026. The product is renamed Elan1 Govern. In the original pages, 'elan1' meaning the product or kernel should be read as Elan1 Govern; 'elan1 Private Limited' remains the entity. Engine outputs are unchanged; every addition is listed on the Revision log, and the new Elan1 Govern switches on Assumptions are OFF in the base case.
B51: ADDED IN THE REVISED EDITION | C51: What it shows
B52: Govern overlay | C52: Elan1 Govern increments behind three switches — governance layer, reads billed, reads cost; zero when OFF
...

Sheet Assumptions
A1: Assumptions and drivers
A2: Every price, ramp, rate and funding event that the 54-month engine reads. Change a driver here and the engine must be re-run.
A3: Units are stated on each line. Rs = Indian rupees; cr = crore (10,000,000); L = lakh (100,000).
A5: PRICE BOOK — Rs, annual unless stated
A6: Item | B6: Price (Rs) | C6: Unit
A7: Platform floor, L1 Guarded | B7: 180000 | C7: per tenant per year
A8: Platform floor, L2 Attested | B8: 600000 | C8: per tenant per year
A9: Platform floor, L3 Proven | B9: 2400000 | C9: per tenant per year
A10: Sovereign / on-premises deployment | B10: 12000000 | C10: per deployment per year
A11: Included governed actions, L1 | B11: 480000 | C11: actions per tenant per year
A12: Included governed actions, L2 | B12: 1500000 | C12: actions per tenant per year
A13: Included governed actions, L3 | B13: 4200000 | C13: actions per tenant per year
A14: Governed action beyond allowance, L1 | B14: 1.6 | C14: Rs per action
A15: Governed action beyond allowance, L2 | B15: 1.2 | C15: Rs per action
A16: Governed action beyond allowance, L3 | B16: 0.9 | C16: Rs per action
A17: Governed action, sovereign deployment | B17: 0.55 | C17: Rs per action
A18: Governed action, internal transfer to rung1 | B18: 0.4 | C18: Rs per action
... A23: Partner certification | B23: 150000 | C23: per firm per year
A24: Refusals are metered at quantity zero and are never billed. List prices are flat to March 2029 and escalate 4% per annum thereafter.
A25: Included-action allowances are consumed first; only actions beyond the allowance are billed at the per-action rate.
A27: DEMAND, MIX AND CHANNEL DRIVERS — monthly ramp, end of month
A28: Month | B28: Tenants, total | C28: of which L1 | D28: of which L2 | E28: of which L3 | F28: Sovereign | G28: Partner firms | H28: Internal GA / month | I28: Pack attach | J28: Channel share | K28: Cost per GA (Rs)
A29: Oct 2026 | B29: 0 | C29: 0 | D29: 0 | E29: 0 | F29: 0 | G29: 0 | H29: 0 | I29: 0 | J29: 0 | K29: 0.092
A30: Nov 2026 | B30: 0 | C30: 0 | D30: 0 | E30: 0 | F30: 0 | G30: 0 | H30: 0 | I30: 0 | J30: 0 | K30: 0.09076
A31: Dec 2026 | B31: 0 | C31: 0 | D31: 0 | E31: 0 | F31: 0 | G31: 0 | H31: 0 | I31: 0 | J31: 0 | K31: 0.08953
A32: Jan 2027 | B32: 0 | C32: 0 | D32: 0 | E32: 0 | F32: 0 | G32: 0 | H32: 60000 | I32: 0 | J32: 0 | K32: 0.08832
A33: Feb 2027 | B33: 0 | C33: 0 | D33: 0 | E33: 0 | F33: 0 | G33: 0 | H33: 120000 | I33: 0 | J33: 0 | K33: 0.08713
A34: Mar 2027 | B34: 0 | C34: 0 | D34: 0 | E34: 0 | F34: 0 | G34: 0 | H34: 180000 | I34: 0 | J34: 0 | K34: 0.08596
A35: Apr 2027 | B35: 0 | C35: 0 | D35: 0 | E35: 0 | F35: 0 | G35: 0 | H35: 260000 | I35: 0 | J35: 0 | K35: 0.0848
A36: May 2027 | B36: 0 | C36: 0 | D36: 0 | E36: 0 | F36: 0 | G36: 0 | H36: 340000 | I36: 0 | J36: 0 | K36: 0.08365
A37: Jun 2027 | B37: 0 | C37: 0 | D37: 0 | E37: 0 | F37: 0 | G37: 0 | H37: 420000 | I37: 0 | J37: 0 | K37: 0.08252
A38: Jul 2027 | B38: 3 | C38: 3 | D38: 0 | E38: 0 | F38: 0 | G38: 0 | H38: 580000 | I38: 0 | J38: 0 | K38: 0.08141
A39: Aug 2027 | B39: 6 | C39: 6 | D39: 0 | E39: 0 | F39: 0 | G39: 0 | H39: 740000 | I39: 0 | J39: 0 | K39: 0.08031
A40: Sep 2027 | B40: 9 | C40: 9 | D40: 0 | E40: 0 | F40: 0 | G40: 0 | H40: 900000 | I40: 0 | J40: 0 | K40: 0.07922
... A82: Mar 2031 | B82: 545 | C82: 278.86 | D82: 211.19 | E82: 54.95 | F82: 11 | G82: 140 | H82: 30000000 | I82: 1.32 | J82: 0.45 | K82: 0.052
A83: Tenant ramp anchors: first external paying tenant July 2027; 39 by March 2028; 148 by March 2029; 312 by March 2030; 545 by March 2031.
A84: Assurance mix: L1 only until April 2028; L2 general availability April 2028 ramps to 36-39% of tenants; L3 entry October 2029 reaching about 10%.
A85: External governed actions per tenant per month: L1 72,000 · L2 300,000 · L3 1,250,000, each growing 8% per annum.
A86: Channel: partners keep 18% of list on partner-sourced revenue; partner-sourced share of external revenue rises from 0% to 45% by March 2031, shown as a contra-revenue line.
A87: Cost per governed action is the blended runtime and infrastructure unit cost (stack1 internal cost plus 15%), falling from Rs 0.092 to Rs 0.052.
...

Sheet Summary P&L
A1: Summary profit and loss — five financial years
A2: The full plan at annual grain: revenue to EBIT, exit ARR, closing cash, headcount and paying tenants. Derived lines are live formulas.
A3: Rs crore, except margins (%), headcount and tenant counts. Financial years end 31 March. US$ block below at Rs 90.00 = US$1.00.
A5: Rs crore | B5: FY2026-27 | C5: FY2027-28 | D5: FY2028-29 | E5: FY2029-30 | F5: FY2030-31
A6: Revenue | B6: 0.0144 | C6: 1.8901325 | D6: 18.077531 | E6: 81.179988 | F6: 230.31755
A7: Cost of revenue | B7: 0.10940403 | C7: 1.6749955 | D7: 6.8355136 | E7: 16.566936 | F7: 32.245312
A8: Gross profit | B8: =B6-B7 -> -0.095004034 | C8: =C6-C7 -> 0.21513695 | D8: =D6-D7 -> 11.242018 | E8: =E6-E7 -> 64.613051 | F8: =F6-F7 -> 198.07224
A9: Gross margin % | B9: =IF(B6<0.05,"n/m",B8/B6) -> n/m | C9: =IF(C6<0.05,"n/m",C8/C6) -> 0.1138211 | D9: =IF(D6<0.05,"n/m",D8/D6) -> 0.62187793 | E9: =IF(E6<0.05,"n/m",E8/E6) -> 0.79592339 | F9: =IF(F6<0.05,"n/m",F8/F6) -> 0.85999629
A10: Operating expenses | B10: 4.3888685 | C10: 26.94154 | D10: 61.975186 | E10: 111.09423 | F10: 175.49629
A11: EBITDA | B11: =B8-B10 -> -4.4838725 | C11: =C8-C10 -> -26.726403 | D11: =D8-D10 -> -50.733168 | E11: =E8-E10 -> -46.481176 | F11: =F8-F10 -> 22.575951
A12: ESOP charge (non-cash) | B12: 0.33150223 | C12: 2.2835872 | D12: 5.2411212 | E12: 8.7037761 | F12: 12.393149
A13: EBIT | B13: =B11-B12 -> -4.8153748 | C13: =C11-C12 -> -29.009991 | D13: =D11-D12 -> -55.974289 | E13: =E11-E12 -> -55.184952 | F13: =F11-F12 -> 10.182802
A14: EBITDA margin % | B14: =IF(B6<0.05,"n/m",B11/B6) -> n/m | C14: =IF(C6<0.05,"n/m",C11/C6) -> -14.139963 | D14: =IF(D6<0.05,"n/m",D11/D6) -> -2.8064212 | E14: =IF(E6<0.05,"n/m",E11/E6) -> -0.57256939 | F14: =IF(F6<0.05,"n/m",F11/F6) -> 0.098020974
A16: POSITION AT YEAR END
A17: Exit ARR | B17: 0.0864 | C17: 5.0192216 | D17: 33.679223 | E17: 133.03688 | F17: 334.22544
A18: Closing cash | B18: 66.443647 | C18: 38.666766 | D18: 55.229826 | E18: 38.411427 | F18: 30.409496
A19: Funding received in year | B19: 71 | C19: 0 | D19: 72 | E19: 45 | F19: 0
A20: Capex | B20: 0.07248 | C20: 0.45328 | D20: 0.73232 | E20: 1.01648 | F20: 1.2744
A21: Headcount at year end | B21: 27 | C21: 95 | D21: 170 | E21: 243 | F21: 305
A22: Paying tenants at year end | B22: 0 | C22: 39 | D22: 148 | E22: 312 | F22: 545
A23: Certified partner firms at year end | B23: 0 | C23: 6 | D23: 28 | E23: 70 | F23: 140
A24: Sovereign deployments at year end | B24: 0 | C24: 0 | D24: 0 | E24: 4 | F24: 11
A26: US DOLLAR VIEW AT Rs 90.00 = US$1.00 (Rs crore ÷ 9 = US$ million)
A27: US$ million | B27: FY2026-27 | C27: FY2027-28 | D27: FY2028-29 | E27: FY2029-30 | F27: FY2030-31
A28: Revenue | B28: =B6/9 -> 0.0016 | C28: =C6/9 -> 0.21001472 | D28: =D6/9 -> 2.0086146 | E28: =E6/9 -> 9.0199987 | F28: =F6/9 -> 25.590839
A29: Cost of revenue | B29: =B7/9 -> 0.012156004 | C29: =C7/9 -> 0.18611061 | D29: =D7/9 -> 0.75950152 | E29: =E7/9 -> 1.8407707 | F29: =F7/9 -> 3.5828125
A30: Gross profit | B30: =B8/9 -> -0.010556004 | C30: =C8/9 -> 0.023904105 | D30: =D8/9 -> 1.2491131 | E30: =E8/9 -> 7.1792279 | F30: =F8/9 -> 22.008027
A31: Operating expenses | B31: =B10/9 -> 0.48765205 | C31: =C10/9 -> 2.9935045 | D31: =D10/9 -> 6.8861318 | E31: =E10/9 -> 12.343803 | F31: =F10/9 -> 19.499588
A32: EBITDA | B32: =B11/9 -> -0.49820806 | C32: =C11/9 -> -2.9696004 | D32: =D11/9 -> -5.6370187 | E32: =E11/9 -> -5.1645751 | F32: =F11/9 -> 2.508439
A33: ESOP charge (non-cash) | B33: =B12/9 -> 0.036833581 | C33: =C12/9 -> 0.25373191 | D33: =D12/9 -> 0.58234679 | E33: =E12/9 -> 0.96708623 | F33: =F12/9 -> 1.3770166
A34: EBIT | B34: =B13/9 -> -0.53504164 | C34: =C13/9 -> -3.2233323 | D34: =D13/9 -> -6.2193655 | E34: =E13/9 -> -6.1316613 | F34: =F13/9 -> 1.1314224
A35: Exit ARR | B35: =B17/9 -> 0.0096 | C35: =C17/9 -> 0.55769129 | D35: =D17/9 -> 3.7421359 | E35: =E17/9 -> 14.781875 | F35: =F17/9 -> 37.13616
A36: Closing cash | B36: =B18/9 -> 7.3826275 | C36: =C18/9 -> 4.2963074 | D36: =D18/9 -> 6.1366473 | E36: =E18/9 -> 4.2679364 | F36: =F18/9 -> 3.3788329
A37: US$ figures are a presentation of the rupee plan at a fixed rate; no currency hedging or translation gain is modelled.
A39: ELAN1 GOVERN OVERLAY — zero unless switched on at Assumptions B120, B130 or B134
A40: Rs crore | B40: FY2026-27 | C40: FY2027-28 | D40: FY2028-29 | E40: FY2029-30 | F40: FY2030-31
A41: Incremental revenue | B41: ='Govern overlay'!B88 -> 0 | C41: ='Govern overlay'!C88 -> 0 | D41: ='Govern overlay'!D88 -> 0 | E41: ='Govern overlay'!E88 -> 0 | F41: ='Govern overlay'!F88 -> 0
A42: Incremental cost of revenue | B42: ='Govern overlay'!B89 -> 0 | C42: ='Govern overlay'!C89 -> 0 | D42: ='Govern overlay'!D89 -> 0 | E42: ='Govern overlay'!E89 -> 0 | F42: ='Govern overlay'!F89 -> 0
A43: Incremental EBITDA | B43: =B41-B42 -> 0 | C43: =C41-C42 -> 0 | D43: =D41-D42 -> 0 | E43: =E41-E42 -> 0 | F43: =F41-F42 -> 0
A44: Revenue including overlay | B44: =B6+B41 -> 0.0144 | C44: =C6+C41 -> 1.8901325 | D44: =D6+D41 -> 18.077531 | E44: =E6+E41 -> 81.179988 | F44: =F6+F41 -> 230.31755
...

Sheet Monthly FY2026-27
A1: Monthly detail — H2 FY2026-27 (October 2026 to March 2027)
A2: The six months from company formation to Series A close: burn, funding and the first internal governed actions.
A3: Rs lakh (1 lakh = 100,000), except headcount and governed actions, which are counts.
A5: Rs lakh | B5: Oct 2026 | C5: Nov 2026 | D5: Dec 2026 | E5: Jan 2027 | F5: Feb 2027 | G5: Mar 2027 | H5: H2 total
A6: Revenue | B6: 0 | C6: 0 | D6: 0 | E6: 0.24 | F6: 0.48 | G6: 0.72 | H6: =SUM(B6:G6) -> 1.44
A7: Cost of revenue | B7: 0.55 | C7: 0.55 | D7: 1.7570504 | E7: 1.8178111 | F7: 3.0998236 | G7: 3.1657183 | H7: =SUM(B7:G7) -> 10.940403
A8: Gross profit | B8: =B6-B7 -> -0.55 | C8: =C6-C7 -> -0.55 | D8: =D6-D7 -> -1.7570504 | E8: =E6-E7 -> -1.5778111 | F8: =F6-F7 -> -2.6198236 | G8: =G6-G7 -> -2.4457183 | H8: =H6-H7 -> -9.5004034
A9: Operating expenses | B9: 47.109267 | C9: 50.575437 | D9: 71.779573 | E9: 80.497293 | F9: 92.542053 | G9: 96.383226 | H9: =SUM(B9:G9) -> 438.88685
A10: EBITDA | B10: =B8-B9 -> -47.659267 | C10: =C8-C9 -> -51.125437 | D10: =D8-D9 -> -73.536624 | E10: =E8-E9 -> -82.075105 | F10: =F8-F9 -> -95.161877 | G10: =G8-G9 -> -98.828944 | H10: =H8-H9 -> -448.38725
A11: Capex | B11: 0.952 | C11: 0.984 | D11: 1.112 | E11: 1.304 | F11: 1.432 | G11: 1.464 | H11: =SUM(B11:G11) -> 7.248
A12: Net burn | B12: 48.611267 | C12: 52.109437 | D12: 74.648624 | E12: 83.379105 | F12: 96.593877 | G12: 100.29294 | H12: =SUM(B12:G12) -> 455.63525
A13: Funding in | B13: 800 | C13: 0 | D13: 0 | E13: 0 | F13: 0 | G13: 6300 | H13: =SUM(B13:G13) -> 7100
A14: Closing cash | B14: 751.38873 | C14: 699.2793 | D14: 624.63067 | E14: 541.25157 | F14: 444.65769 | G14: 6644.3647 | H14: =G14 -> 6644.3647
A16: OPERATING MEASURES
A17: Headcount at month end | B17: 11 | C17: 12 | D17: 16 | E17: 22 | F17: 26 | G17: 27 | H17: =G17 -> 27
A18: Governed actions in month | B18: 0 | C18: 0 | D18: 0 | E18: 60000 | F18: 120000 | G18: 180000 | H18: =SUM(B18:G18) -> 360000
A19: of which internal (rung1) | B19: 0 | C19: 0 | D19: 0 | E19: 60000 | F19: 120000 | G19: 180000 | H19: =SUM(B19:G19) -> 360000
A20: of which external | B20: 0 | C20: 0 | D20: 0 | E20: 0 | F20: 0 | G20: 0 | H20: =SUM(B20:G20) -> 0
A21: Paying tenants at month end | B21: 0 | C21: 0 | D21: 0 | E21: 0 | F21: 0 | G21: 0 | H21: =G21 -> 0
A23: HEADCOUNT BY FUNCTION — end of month
A24: Function | B24: Oct 2026 | C24: Nov 2026 | D24: Dec 2026 | E24: Jan 2027 | F24: Feb 2027 | G24: Mar 2027 | H24: Band Rs L/yr
A25: Kernel engineering | B25: 4 | C25: 5 | D25: 5 | E25: 6 | F25: 6 | G25: 7 | H25: 34
A26: Evidence and cryptography | B26: 1 | C26: 1 | D26: 2 | E26: 2 | F26: 3 | G26: 3 | H26: 38
A27: Pack and regulatory engineering | B27: 1 | C27: 1 | D27: 1 | E27: 2 | F27: 2 | G27: 2 | H27: 30
A28: Platform and SRE | B28: 2 | C28: 2 | D28: 2 | E28: 3 | F28: 3 | G28: 3 | H28: 30
A29: Security, compliance, certification | B29: 0 | C29: 0 | D29: 1 | E29: 1 | F29: 2 | G29: 2 | H29: 32
A30: Product and design | B30: 1 | C30: 1 | D30: 1 | E30: 2 | F30: 2 | G30: 2 | H30: 28
A31: Solutions and field engineering | B31: 0 | C31: 0 | D31: 1 | E31: 1 | F31: 2 | G31: 2 | H31: 26
A32: Go to market and partners | B32: 1 | C32: 1 | D32: 2 | E32: 2 | F32: 3 | G32: 3 | H32: 27
A33: Standards, policy, regulator affairs | B33: 0 | C33: 0 | D33: 0 | E33: 1 | F33: 1 | G33: 1 | H33: 36
A34: Finance, legal and operations | B34: 1 | C34: 1 | D34: 1 | E34: 2 | F34: 2 | G34: 2 | H34: 24
A35: Total headcount | B35: =SUM(B25:B34) -> 11 | C35: =SUM(C25:C34) -> 12 | D35: =SUM(D25:D34) -> 16 | E35: =SUM(E25:E34) -> 22 | F35: =SUM(F25:F34) -> 26 | G35: =SUM(G25:G34) -> 27
A36: Minimum cash across the whole plan occurs in February 2027 at Rs 444.66 lakh (Rs 4.4 crore), the month before the Rs 63 crore tranche 1 closes.

Sheet Quarterly FY2027-28
A1: Quarterly detail — FY2027-28, and the full 18-quarter arc
A2: The first year of external revenue quarter by quarter, then every quarter of the plan so the shape of the build is visible in one view.
A3: Rs crore, except margins (%) and counts. Quarters are financial-year quarters ending June, September, December and March.
A5: Rs crore | B5: Q1 Jun 27 | C5: Q2 Sep 27 | D5: Q3 Dec 27 | E5: Q4 Mar 28 | F5: FY2027-28
A6: Revenue | B6: 0.0408 | C6: 0.22217028 | D6: 0.56226022 | E6: 1.064902 | F6: =SUM(B6:E6) -> 1.8901325
A7: Cost of revenue | B7: 0.14973483 | C7: 0.29014539 | D7: 0.49256854 | E7: 0.74254676 | F7: =SUM(B7:E7) -> 1.6749955
A8: Gross profit | B8: =B6-B7 -> -0.10893483 | C8: =C6-C7 -> -0.067975112 | D8: =D6-D7 -> 0.069691684 | E8: =E6-E7 -> 0.3223552 | F8: =F6-F7 -> 0.21513695
A9: Gross margin % | B9: =IFERROR(B8/B6,"n/m") -> -2.6699713 | C9: =IFERROR(C8/C6,"n/m") -> -0.30595952 | D9: =IFERROR(D8/D6,"n/m") -> 0.12394916 | E9: =IFERROR(E8/E6,"n/m") -> 0.30270881 | F9: =IFERROR(F8/F6,"n/m") -> 0.1138211
A10: Operating expenses | B10: 4.1373859 | C10: 5.7045408 | D10: 7.6399773 | E10: 9.4596363 | F10: =SUM(B10:E10) -> 26.94154
A11: EBITDA | B11: =B8-B10 -> -4.2463207 | C11: =C8-C10 -> -5.7725159 | D11: =D8-D10 -> -7.5702856 | E11: =E8-E10 -> -9.1372811 | F11: =F8-F10 -> -26.726403
A12: ESOP charge (non-cash) | B12: 0.33950684 | C12: 0.48196528 | D12: 0.64589655 | E12: 0.81621852 | F12: =SUM(B12:E12) -> 2.2835872
A13: EBIT | B13: =B11-B12 -> -4.5858276 | C13: =C11-C12 -> -6.2544812 | D13: =D11-D12 -> -8.2161822 | E13: =E11-E12 -> -9.9534997 | F13: =F11-F12 -> -29.009991
A15: POSITION AT QUARTER END
A16: Exit ARR | B16: 0.2016 | C16: 1.2379027 | D16: 2.7664545 | E16: 5.0192216 | F16: =E16 -> 5.0192216
A17: Closing cash | B17: 62.002527 | C17: 56.039053 | D17: 48.195675 | E17: 38.666766 | F17: =E17 -> 38.666766
A18: Headcount | B18: 44 | C18: 59 | D18: 76 | E18: 95 | F18: =E18 -> 95
A19: Paying tenants | B19: 0 | C19: 9 | D19: 21 | E19: 39 | F19: =E19 -> 39
A20: Certified partner firms | B20: 0 | C20: 0 | D20: 2 | E20: 6 | F20: =E20 -> 6
A21: Governed actions in quarter (millions) | B21: 1.02 | C21: 3.6048 | D21: 7.8953 | E21: 13.8045 | F21: =SUM(B21:E21) -> 26.3246
A23: ALL 18 QUARTERS OF THE PLAN
A24: Quarter | B24: Revenue | C24: EBITDA | D24: Exit ARR | E24: Closing cash | F24: Paying tenants
A25: FY2026-27 Q3 | B25: 0 | C25: -1.7232133 | D25: 0 | E25: 6.2463067 | F25: 0
A26: FY2026-27 Q4 | B26: 0.0144 | C26: -2.7606593 | D26: 0.0864 | E26: 66.443647 | F26: 0
A27: FY2027-28 Q1 | B27: 0.0408 | C27: -4.2463207 | D27: 0.2016 | E27: 62.002527 | F27: 0
A28: FY2027-28 Q2 | B28: 0.22217028 | C28: -5.7725159 | D28: 1.2379027 | E28: 56.039053 | F28: 9
A29: FY2027-28 Q3 | B29: 0.56226022 | C29: -7.5702856 | D29: 2.7664545 | E29: 48.195675 | F29: 21
A30: FY2027-28 Q4 | B30: 1.064902 | C30: -9.1372811 | D30: 5.0192216 | E30: 38.666766 | F30: 39
A31: FY2028-29 Q1 | B31: 2.0478631 | C31: -10.714807 | D31: 9.6046266 | E31: 27.06868 | F31: 59
A32: FY2028-29 Q2 | B32: 3.3398867 | C32: -11.999438 | D32: 15.35343 | E32: 14.132096 | F32: 84
A33: FY2028-29 Q3 | B33: 5.1549781 | C33: -13.498415 | D33: 23.415086 | E33: 71.367227 | F33: 114
A34: FY2028-29 Q4 | B34: 7.5348036 | C34: -14.520507 | D34: 33.679223 | E34: 55.229826 | F34: 148
A35: FY2029-30 Q1 | B35: 10.735863 | C35: -14.275832 | D35: 48.138973 | E35: 38.587385 | F35: 186
A36: FY2029-30 Q2 | B36: 16.756142 | C36: -13.072542 | D36: 74.786412 | E36: 66.433493 | F36: 226
... A42: FY2030-31 Q4 | B42: 78.08113 | C42: 17.401821 | D42: 334.22544 | E42: 30.409496 | F42: 545
A43: Plan total / final quarter | B43: =SUM(B25:B42) -> 331.47961 | C43: =SUM(C25:C42) -> -105.84867 | D43: =D42 -> 334.22544 | E43: =E42 -> 30.409496 | F43: =F42 -> 545
A44: Revenue and EBITDA columns sum across the 18 quarters; exit ARR, cash and tenants are point-in-time and carry the final quarter.

Sheet Annual FY2028-31
A1: The three scale years — FY2028-29 to FY2030-31
A2: Full detail for the years the Series A is raised against: profit and loss, every revenue and cost line, people, customers and unit economics.
A3: Rs crore, except margins (%), counts, and per-action rates in Rs. Financial years end 31 March.
A5: Rs crore | B5: FY2028-29 | C5: FY2029-30 | D5: FY2030-31 | E5: CAGR / total
A6: Revenue | B6: 18.077531 | C6: 81.179988 | D6: 230.31755 | E6: =(D6/B6)^(1/2)-1 -> 2.5693896
A7: Cost of revenue | B7: 6.8355136 | C7: 16.566936 | D7: 32.245312 | E7: =SUM(B7:D7) -> 55.647762
A8: Gross profit | B8: =B6-B7 -> 11.242018 | C8: =C6-C7 -> 64.613051 | D8: =D6-D7 -> 198.07224 | E8: =SUM(B8:D8) -> 273.92731
A9: Gross margin % | B9: =IFERROR(B8/B6,"n/m") -> 0.62187793 | C9: =IFERROR(C8/C6,"n/m") -> 0.79592339 | D9: =IFERROR(D8/D6,"n/m") -> 0.85999629 | E9: =IFERROR(E8/SUM(B6:D6),"n/m") -> 0.831153
A10: Operating expenses | B10: 61.975186 | C10: 111.09423 | D10: 175.49629 | E10: =SUM(B10:D10) -> 348.5657
A11: EBITDA | B11: =B8-B10 -> -50.733168 | C11: =C8-C10 -> -46.481176 | D11: =D8-D10 -> 22.575951 | E11: =SUM(B11:D11) -> -74.638393
A12: ESOP charge (non-cash) | B12: 5.2411212 | C12: 8.7037761 | D12: 12.393149 | E12: =SUM(B12:D12) -> 26.338046
A13: EBIT | B13: =B11-B12 -> -55.974289 | C13: =C11-C12 -> -55.184952 | D13: =D11-D12 -> 10.182802 | E13: =SUM(B13:D13) -> -100.97644
A14: Capex | B14: 0.73232 | C14: 1.01648 | D14: 1.2744 | E14: =SUM(B14:D14) -> 3.0232
A15: Closing cash | B15: 55.229826 | C15: 38.411427 | D15: 30.409496 | E15: =D15 -> 30.409496
A16: Exit ARR | B16: 33.679223 | C16: 133.03688 | D16: 334.22544 | E16: =D16 -> 334.22544
A18: REVENUE BY LINE
A19: Rs crore | B19: FY2028-29 | C19: FY2029-30 | D19: FY2030-31 | E19: 3-year total
A20: Platform licence | B20: 2.367505 | C20: 9.0524532 | D20: 23.552328 | E20: =SUM(B20:D20) -> 34.972286
A21: Governed actions - external | B21: 11.960886 | C21: 58.704606 | D21: 176.9843 | E21: =SUM(B21:D21) -> 247.64979
A22: Governed actions - internal (rung1) | B22: 2.184 | C22: 5.58 | D22: 11.2 | E22: =SUM(B22:D22) -> 18.964
A23: Evidence SKU | B23: 1.0880612 | C23: 6.3160018 | D23: 17.841922 | E23: =SUM(B23:D23) -> 25.245986
A24: Regulatory packs | B24: 0.8291025 | C24: 3.2370353 | D24: 7.6295803 | E24: =SUM(B24:D24) -> 11.695718
A25: Sovereign deployments | B25: 0 | C25: 2.4626515 | D25: 9.4554723 | E25: =SUM(B25:D25) -> 11.918124
A26: Partner certification | B26: 0.255 | C26: 0.75431795 | D26: 1.6939738 | E26: =SUM(B26:D26) -> 2.7032918
A27: Channel margin (contra) | B27: -0.60702367 | C27: -4.9270781 | D27: -18.040023 | E27: =SUM(B27:D27) -> -23.574125
A28: Total revenue | B28: =SUM(B20:B27) -> 18.077531 | C28: =SUM(C20:C27) -> 81.179988 | D28: =SUM(D20:D27) -> 230.31755 | E28: =SUM(E20:E27) -> 329.57507
A30: OPERATING EXPENSE BY LINE
A31: Rs crore | B31: FY2028-29 | C31: FY2029-30 | D31: FY2030-31 | E31: 3-year total
A32: International expansion | B32: 0.54 | C32: 2.43 | D32: 4.92 | E32: =SUM(B32:D32) -> 7.89
A33: People (ex-COGS) | B33: 44.822125 | C33: 74.189567 | D33: 105.6075 | E33: =SUM(B33:D33) -> 224.6192
A34: Certification and audit | B34: 1.44 | C34: 1.82 | D34: 2.38 | E34: =SUM(B34:D34) -> 5.64
A35: Legal, IP and entities | B35: 1.47 | C35: 2.55 | D35: 2.26 | E35: =SUM(B35:D35) -> 6.28
A36: Standards and regulator affairs | B36: 0.552 | C36: 0.93 | D36: 1.14 | E36: =SUM(B36:D36) -> 2.622
A37: Sales and marketing programmes | B37: 4.5692667 | C37: 14.297698 | D37: 35.36007 | E37: =SUM(B37:D37) -> 54.227035
A38: R&D tooling and evaluation | B38: 1.8567 | C38: 2.7003 | D38: 3.466 | E38: =SUM(B38:D38) -> 8.023
A39: Insurance | B39: 0.33069778 | C39: 0.89861989 | D39: 2.240858 | E39: =SUM(B39:D39) -> 3.4701757
A40: Facilities, IT and G&A | B40: 3.163463 | C40: 5.4863998 | D40: 8.9727633 | E40: =SUM(B40:D40) -> 17.622626
A41: Contingency | B41: 3.2309339 | C41: 5.7916422 | D41: 9.1490957 | E41: =SUM(B41:D41) -> 18.171672
A42: Total operating expenses | B42: =SUM(B32:B41) -> 61.975186 | C42: =SUM(C32:C41) -> 111.09423 | D42: =SUM(D32:D41) -> 175.49629 | E42: =SUM(E32:E41) -> 348.5657
A44: HEADCOUNT BY FUNCTION — end of financial year
...

Sheet Revenue build
A1: Revenue build by line
A2: Every revenue line by financial year and by quarter, including the channel-margin contra. Totals are formulas so the build ties to the Summary P&L.
A3: Rs crore. The channel-margin contra is negative: partners keep 18% of list on partner-sourced revenue.
A5: BY FINANCIAL YEAR
A6: Rs crore | B6: FY2026-27 | C6: FY2027-28 | D6: FY2028-29 | E6: FY2029-30 | F6: FY2030-31 | G6: Plan total
A7: Platform licence | B7: 0 | C7: 0.252 | D7: 2.367505 | E7: 9.0524532 | F7: 23.552328 | G7: =SUM(B7:F7) -> 35.224286
A8: Governed actions - external | B8: 0 | C8: 1.0503507 | D8: 11.960886 | E8: 58.704606 | F8: 176.9843 | G8: =SUM(B8:F8) -> 248.70014
A9: Governed actions - internal (rung1) | B9: 0.0144 | C9: 0.5216 | D9: 2.184 | E9: 5.58 | F9: 11.2 | G9: =SUM(B9:F9) -> 19.5
A10: Evidence SKU | B10: 0 | C10: 0 | D10: 1.0880612 | E10: 6.3160018 | F10: 17.841922 | G10: =SUM(B10:F10) -> 25.245986
A11: Regulatory packs | B11: 0 | C11: 0.0560385 | D11: 0.8291025 | E11: 3.2370353 | F11: 7.6295803 | G11: =SUM(B11:F11) -> 11.751757
A12: Sovereign deployments | B12: 0 | C12: 0 | D12: 0 | E12: 2.4626515 | F12: 9.4554723 | G12: =SUM(B12:F12) -> 11.918124
A13: Partner certification | B13: 0 | C13: 0.02 | D13: 0.255 | E13: 0.75431795 | F13: 1.6939738 | G13: =SUM(B13:F13) -> 2.7232918
A14: Channel margin (contra) | B14: 0 | C14: -0.0098566985 | D14: -0.60702367 | E14: -4.9270781 | F14: -18.040023 | G14: =SUM(B14:F14) -> -23.583981
A15: Total revenue | B15: =SUM(B7:B14) -> 0.0144 | C15: =SUM(C7:C14) -> 1.8901325 | D15: =SUM(D7:D14) -> 18.077531 | E15: =SUM(E7:E14) -> 81.179988 | F15: =SUM(F7:F14) -> 230.31755 | G15: =SUM(G7:G14) -> 331.47961
A17: REVENUE MIX — share of total revenue by financial year
A18: % of revenue | B18: FY2026-27 | C18: FY2027-28 | D18: FY2028-29 | E18: FY2029-30 | F18: FY2030-31 | G18: Plan total
A19: Platform licence | B19: =IFERROR(B7/B15,"n/m") -> 0 | C19: =IFERROR(C7/C15,"n/m") -> 0.13332399 | D19: =IFERROR(D7/D15,"n/m") -> 0.13096395 | E19: =IFERROR(E7/E15,"n/m") -> 0.1115109 | F19: =IFERROR(F7/F15,"n/m") -> 0.10226024 | G19: =IFERROR(G7/G15,"n/m") -> 0.10626381
A20: Governed actions - external | B20: =IFERROR(B8/B15,"n/m") -> 0 | C20: =IFERROR(C8/C15,"n/m") -> 0.55570214 | D20: =IFERROR(D8/D15,"n/m") -> 0.66164379 | E20: =IFERROR(E8/E15,"n/m") -> 0.72314135 | F20: =IFERROR(F8/F15,"n/m") -> 0.768436 | G20: =IFERROR(G8/G15,"n/m") -> 0.75027284
A21: Governed actions - internal (rung1) | B21: =IFERROR(B9/B15,"n/m") -> 1 | C21: =IFERROR(C9/C15,"n/m") -> 0.2759595 | D21: =IFERROR(D9/D15,"n/m") -> 0.12081296 | E21: =IFERROR(E9/E15,"n/m") -> 0.068736152 | F21: =IFERROR(F9/F15,"n/m") -> 0.048628512 | G21: =IFERROR(G9/G15,"n/m") -> 0.058827148
A22: Evidence SKU | B22: =IFERROR(B10/B15,"n/m") -> 0 | C22: =IFERROR(C10/C15,"n/m") -> 0 | D22: =IFERROR(D10/D15,"n/m") -> 0.060188597 | E22: =IFERROR(E10/E15,"n/m") -> 0.077802448 | F22: =IFERROR(F10/F15,"n/m") -> 0.07746662 | G22: =IFERROR(G10/G15,"n/m") -> 0.076161505
A23: Regulatory packs | B23: =IFERROR(B11/B15,"n/m") -> 0 | C23: =IFERROR(C11/C15,"n/m") -> 0.029647922 | D23: =IFERROR(D11/D15,"n/m") -> 0.045863701 | E23: =IFERROR(E11/E15,"n/m") -> 0.039874795 | F23: =IFERROR(F11/F15,"n/m") -> 0.033126352 | G23: =IFERROR(G11/G15,"n/m") -> 0.035452427
A24: Sovereign deployments | B24: =IFERROR(B12/B15,"n/m") -> 0 | C24: =IFERROR(C12/C15,"n/m") -> 0 | D24: =IFERROR(D12/D15,"n/m") -> 0 | E24: =IFERROR(E12/E15,"n/m") -> 0.030335696 | F24: =IFERROR(F12/F15,"n/m") -> 0.041054067 | G24: =IFERROR(G12/G15,"n/m") -> 0.03595432
A25: Partner certification | B25: =IFERROR(B13/B15,"n/m") -> 0 | C25: =IFERROR(C13/C15,"n/m") -> 0.010581269 | D25: =IFERROR(D13/D15,"n/m") -> 0.014105908 | E25: =IFERROR(E13/E15,"n/m") -> 0.00929192 | F25: =IFERROR(F13/F15,"n/m") -> 0.0073549487 | G25: =IFERROR(G13/G15,"n/m") -> 0.0082155635
A26: Channel margin (contra) | B26: =IFERROR(B14/B15,"n/m") -> 0 | C26: =IFERROR(C14/C15,"n/m") -> -0.0052148189 | D26: =IFERROR(D14/D15,"n/m") -> -0.033578902 | E26: =IFERROR(E14/E15,"n/m") -> -0.06069326 | F26: =IFERROR(F14/F15,"n/m") -> -0.078326739 | G26: =IFERROR(G14/G15,"n/m") -> -0.071147609
A27: Total | B27: =IFERROR(B15/B15,"n/m") -> 1 | C27: =IFERROR(C15/C15,"n/m") -> 1 | D27: =IFERROR(D15/D15,"n/m") -> 1 | E27: =IFERROR(E15/E15,"n/m") -> 1 | F27: =IFERROR(F15/F15,"n/m") -> 1 | G27: =IFERROR(G15/G15,"n/m") -> 1
A29: BY QUARTER — all 18 quarters of the plan
A30: Rs crore | B30: 2026/27 Q3 | C30: 2026/27 Q4 | D30: 2027/28 Q1 | E30: 2027/28 Q2 | F30: 2027/28 Q3 | G30: 2027/28 Q4 | H30: 2028/29 Q1 | I30: 2028/29 Q2 | J30: 2028/29 Q3 | K30: 2028/29 Q4 | L30: 2029/30 Q1 | M30: 2029/30 Q2 | N30: 2029/30 Q3 | O30: 2029/30 Q4 | P30: 2030/31 Q1 | Q30: 2030/31 Q2 | R30: 2030/31 Q3 | S30: 2030/31 Q4 | T30: Plan total
A31: Platform licence | B31: 0 | C31: 0 | D31: 0 | E31: 0.027 | F31: 0.0765 | G31: 0.1485 | H31: 0.27937833 | I31: 0.44752417 | J31: 0.67494333 | K31: 0.96565917 | L31: 1.3532829 | M31: 1.8860046 | N31: 2.527173 | O31: 3.2859928 | P31: 4.1797442 | Q31: 5.1884444 | R31: 6.3778575 | S31: 7.8062817 | T31: =SUM(B31:S31) -> 35.224286
A32: Governed actions - external | B32: 0 | C32: 0 | D32: 0 | E32: 0.10637028 | F32: 0.31285534 | G32: 0.63112504 | H32: 1.2787152 | I32: 2.1599341 | J32: 3.4163526 | K32: 5.1058844 | L32: 7.4302923 | M32: 11.92096 | N32: 16.77211 | O32: 22.581245 | P32: 29.508336 | Q32: 38.048692 | R32: 48.462831 | S32: 60.964442 | T32: =SUM(B32:S32) -> 248.70014
A33: Governed actions - internal (rung1) | B33: 0 | C33: 0.0144 | D33: 0.0408 | E33: 0.0888 | F33: 0.156 | G33: 0.236 | H33: 0.34 | I33: 0.454 | J33: 0.608 | K33: 0.782 | L33: 1 | M33: 1.24 | N33: 1.52 | O33: 1.82 | P33: 2.18 | Q33: 2.57 | R33: 3 | S33: 3.45 | T33: =SUM(B33:S33) -> 19.5
A34: Evidence SKU | B34: 0 | C34: 0 | D34: 0 | E34: 0 | F34: 0 | G34: 0 | H34: 0.067384583 | I34: 0.16435854 | J34: 0.31780583 | K34: 0.53851229 | L34: 0.83684453 | M34: 1.2833755 | N34: 1.7939114 | O34: 2.4018705 | P34: 3.1074267 | Q34: 3.9054195 | R34: 4.8521718 | S34: 5.9769045 | T34: =SUM(B34:S34) -> 25.245986
A35: Regulatory packs | B35: 0 | C35: 0 | D35: 0 | E35: 0 | F35: 0.015012 | G35: 0.0410265 | H35: 0.08413875 | I35: 0.14967 | J35: 0.239355 | K35: 0.35593875 | L35: 0.50571305 | M35: 0.69190416 | N35: 0.90138588 | O35: 1.1380322 | P35: 1.4033958 | Q35: 1.7040905 | R35: 2.0535208 | S35: 2.4685731 | T35: =SUM(B35:S35) -> 11.751757
A36: Sovereign deployments | B36: 0 | C36: 0 | D36: 0 | E36: 0 | F36: 0 | G36: 0 | H36: 0 | I36: 0 | J36: 0 | K36: 0 | L36: 0 | M36: 0.50691247 | N36: 0.81885112 | O36: 1.1368879 | P36: 1.4611126 | Q36: 2.0023547 | R36: 2.6605279 | S36: 3.3314772 | T36: =SUM(B36:S36) -> 11.918124
A37: Partner certification | B37: 0 | C37: 0 | D37: 0 | E37: 0 | F37: 0.0025 | G37: 0.0175 | H37: 0.03375 | I37: 0.05125 | J37: 0.0725 | K37: 0.0975 | L37: 0.12794245 | M37: 0.16339737 | N37: 0.20722053 | O37: 0.2557576 | P37: 0.31567793 | Q37: 0.38200981 | R37: 0.45760746 | S37: 0.53867861 | T37: =SUM(B37:S37) -> 2.7232918
A38: Channel margin (contra) | B38: 0 | C38: 0 | D38: 0 | E38: 0 | F38: -0.000607122 | G38: -0.0092495765 | H38: -0.035503754 | I38: -0.086850126 | J38: -0.17397868 | K38: -0.3106911 | L38: -0.51821243 | M38: -0.93641142 | N38: -1.4261009 | O38: -2.0463534 | P38: -2.8106059 | Q38: -3.7863078 | R38: -4.9878823 | S38: -6.455227 | T38: =SUM(B38:S38) -> -23.583981
A39: Total revenue | B39: =SUM(B31:B38) -> 0 | C39: =SUM(C31:C38) -> 0.0144 | D39: =SUM(D31:D38) -> 0.0408 | E39: =SUM(E31:E38) -> 0.22217028 | F39: =SUM(F31:F38) -> 0.56226022 | G39: =SUM(G31:G38) -> 1.064902 | H39: =SUM(H31:H38) -> 2.0478631 | I39: =SUM(I31:I38) -> 3.3398867 | ... T39: =SUM(T31:T38) -> 331.47961
A40: Quarterly columns are labelled by financial-year quarter; Q1 ends June, Q2 September, Q3 December and Q4 March.

Sheet Cost build
A1: Cost build — cost of revenue and operating expenses
A2: The COGS split and every operating cost line by financial year, with totals as formulas and each line as a percentage of revenue.
A3: Rs crore, except the percentage blocks. Percentages are of total revenue in the same financial year.
A5: Rs crore | B5: FY2026-27 | C5: FY2027-28 | D5: FY2028-29 | E5: FY2029-30 | F5: FY2030-31 | G5: Plan total
A6: Revenue (memo) | B6: 0.0144 | C6: 1.8901325 | D6: 18.077531 | E6: 81.179988 | F6: 230.31755 | G6: =SUM(B6:F6) -> 331.47961
A8: COST OF REVENUE
A9: Rs crore | B9: FY2026-27 | C9: FY2027-28 | D9: FY2028-29 | E9: FY2029-30 | F9: FY2030-31 | G9: Plan total
A10: Runtime and infrastructure (stack1 internal cost + 15%) | B10: 0.036122722 | C10: 0.65258599 | D10: 3.9364828 | E10: 11.479514 | F10: 24.898784 | G10: =SUM(B10:F10) -> 41.003489
A11: Timestamp anchoring (two authorities) | B11: 0 | C11: 0 | D11: 0.074599542 | E11: 0.15175244 | F11: 0.289041 | G11: =SUM(B11:F11) -> 0.51539298
A12: Delivery and customer success | B12: 0.073281312 | C12: 1.0224095 | D12: 2.8244313 | E12: 4.9356701 | F12: 7.0574877 | G12: =SUM(B12:F12) -> 15.91328
A13: Total cost of revenue | B13: =SUM(B10:B12) -> 0.10940403 | C13: =SUM(C10:C12) -> 1.6749955 | D13: =SUM(D10:D12) -> 6.8355136 | E13: =SUM(E10:E12) -> 16.566936 | F13: =SUM(F10:F12) -> 32.245312 | G13: =SUM(G10:G12) -> 57.432162
A14: Gross profit | B14: =B6-B13 -> -0.095004034 | C14: =C6-C13 -> 0.21513695 | D14: =D6-D13 -> 11.242018 | E14: =E6-E13 -> 64.613051 | F14: =F6-F13 -> 198.07224 | G14: =G6-G13 -> 274.04744
A15: Gross margin % | B15: =IF(B6<0.05,"n/m",B14/B6) -> n/m | C15: =IF(C6<0.05,"n/m",C14/C6) -> 0.1138211 | D15: =IF(D6<0.05,"n/m",D14/D6) -> 0.62187793 | E15: =IF(E6<0.05,"n/m",E14/E6) -> 0.79592339 | F15: =IF(F6<0.05,"n/m",F14/F6) -> 0.85999629 | G15: =IF(G6<0.05,"n/m",G14/G6) -> 0.82673998
A17: OPERATING EXPENSES BY LINE
A18: Rs crore | B18: FY2026-27 | C18: FY2027-28 | D18: FY2028-29 | E18: FY2029-30 | F18: FY2030-31 | G18: Plan total
A19: International expansion | B19: 0 | C19: 0 | D19: 0.54 | E19: 2.43 | F19: 4.92 | G19: =SUM(B19:F19) -> 7.89
A20: People (ex-COGS) | B20: 2.9403753 | C20: 19.737474 | D20: 44.822125 | E20: 74.189567 | F20: 105.6075 | G20: =SUM(B20:F20) -> 247.29705
A21: Certification and audit | B21: 0 | C21: 0.66 | D21: 1.44 | E21: 1.82 | F21: 2.38 | G21: =SUM(B21:F21) -> 6.3
A22: Legal, IP and entities | B22: 0.3 | C22: 0.86 | D22: 1.47 | E22: 2.55 | F22: 2.26 | G22: =SUM(B22:F22) -> 7.44
A23: Standards and regulator affairs | B23: 0.072 | C23: 0.264 | D23: 0.552 | E23: 0.93 | F23: 1.14 | G23: =SUM(B23:F23) -> 2.958
A24: Sales and marketing programmes | B24: 0.220344 | C24: 1.2751679 | D24: 4.5692667 | E24: 14.297698 | F24: 35.36007 | G24: =SUM(B24:F24) -> 55.722547
A25: R&D tooling and evaluation | B25: 0.2643 | C25: 1.0283 | D25: 1.8567 | E25: 2.7003 | F25: 3.466 | G25: =SUM(B25:F25) -> 9.3156
A26: Insurance | B26: 0.0001296 | C26: 0.14301119 | D26: 0.33069778 | E26: 0.89861989 | F26: 2.240858 | G26: =SUM(B26:F26) -> 3.6133165
A27: Facilities, IT and G&A | B27: 0.362916 | C27: 1.569052 | D27: 3.163463 | E27: 5.4863998 | F27: 8.9727633 | G27: =SUM(B27:F27) -> 19.554594
A28: Contingency | B28: 0.22880357 | C28: 1.4045353 | D28: 3.2309339 | E28: 5.7916422 | F28: 9.1490957 | G28: =SUM(B28:F28) -> 19.805011
A29: Total operating expenses | B29: =SUM(B19:B28) -> 4.3888685 | C29: =SUM(C19:C28) -> 26.94154 | D29: =SUM(D19:D28) -> 61.975186 | E29: =SUM(E19:E28) -> 111.09423 | F29: =SUM(F19:F28) -> 175.49629 | G29: =SUM(G19:G28) -> 379.89611
A30: EBITDA | B30: =B14-B29 -> -4.4838725 | C30: =C14-C29 -> -26.726403 | D30: =D14-D29 -> -50.733168 | E30: =E14-E29 -> -46.481176 | F30: =F14-F29 -> 22.575951 | G30: =G14-G29 -> -105.84867
A32: COST AS A PERCENTAGE OF REVENUE
A33: % of revenue | B33: FY2026-27 | C33: FY2027-28 | D33: FY2028-29 | E33: FY2029-30 | F33: FY2030-31 | G33: Plan total
A34: Total cost of revenue | B34: =IF(B6<0.05,"n/m",B13/B6) -> n/m | C34: =IF(C6<0.05,"n/m",C13/C6) -> 0.8861789 | D34: =IF(D6<0.05,"n/m",D13/D6) -> 0.37812207 | E34: =IF(E6<0.05,"n/m",E13/E6) -> 0.20407661 | F34: =IF(F6<0.05,"n/m",F13/F6) -> 0.14000371 | G34: =IF(G6<0.05,"n/m",G13/G6) -> 0.17326002
A35: Runtime and infrastructure (stack1 internal cost + 15%) | B35: =IF(B6<0.05,"n/m",B10/B6) -> n/m | C35: =IF(C6<0.05,"n/m",C10/C6) -> 0.34525939 | D35: =IF(D6<0.05,"n/m",D10/D6) -> 0.21775555 | E35: =IF(E6<0.05,"n/m",E10/E6) -> 0.14140817 | F35: =IF(F6<0.05,"n/m",F10/F6) -> 0.10810632 | G35: =IF(G6<0.05,"n/m",G10/G6) -> 0.12369838
A36: Timestamp anchoring (two authorities) | B36: =IF(B6<0.05,"n/m",B11/B6) -> n/m | C36: =IF(C6<0.05,"n/m",C11/C6) -> 0 | D36: =IF(D6<0.05,"n/m",D11/D6) -> 0.0041266443 | E36: =IF(E6<0.05,"n/m",E11/E6) -> 0.0018693332 | F36: =IF(F6<0.05,"n/m",F11/F6) -> 0.0012549673 | G36: =IF(G6<0.05,"n/m",G11/G6) -> 0.0015548256
A37: Delivery and customer success | B37: =IF(B6<0.05,"n/m",B12/B6) -> n/m | C37: =IF(C6<0.05,"n/m",C12/C6) -> 0.54091951 | D37: =IF(D6<0.05,"n/m",D12/D6) -> 0.15623988 | E37: =IF(E6<0.05,"n/m",E12/E6) -> 0.060799099 | F37: =IF(F6<0.05,"n/m",F12/F6) -> 0.030642422 | G37: =IF(G6<0.05,"n/m",G12/G6) -> 0.048006815
A38: International expansion | B38: =IF(B6<0.05,"n/m",B19/B6) -> n/m | C38: =IF(C6<0.05,"n/m",C19/C6) -> 0 | D38: =IF(D6<0.05,"n/m",D19/D6) -> 0.029871335 | E38: =IF(E6<0.05,"n/m",E19/E6) -> 0.029933486 | F38: =IF(F6<0.05,"n/m",F19/F6) -> 0.021361811 | G38: =IF(G6<0.05,"n/m",G19/G6) -> 0.023802369
A39: People (ex-COGS) | B39: =IF(B6<0.05,"n/m",B20/B6) -> n/m | C39: =IF(C6<0.05,"n/m",C20/C6) -> 10.442376 | D39: =IF(D6<0.05,"n/m",D20/D6) -> 2.4794383 | E39: =IF(E6<0.05,"n/m",E20/E6) -> 0.91388985 | F39: =IF(F6<0.05,"n/m",F20/F6) -> 0.45852998 | G39: =IF(G6<0.05,"n/m",G20/G6) -> 0.74604
A40: Certification and audit | B40: =IF(B6<0.05,"n/m",B21/B6) -> n/m | C40: =IF(C6<0.05,"n/m",C21/C6) -> 0.34918188 | D40: =IF(D6<0.05,"n/m",D21/D6) -> 0.079656894 | E40: =IF(E6<0.05,"n/m",E21/E6) -> 0.022419318 | F40: =IF(F6<0.05,"n/m",F21/F6) -> 0.010333559 | G40: =IF(G6<0.05,"n/m",G21/G6) -> 0.019005694
A41: Legal, IP and entities | B41: =IF(B6<0.05,"n/m",B22/B6) -> n/m | C41: =IF(C6<0.05,"n/m",C22/C6) -> 0.45499457 | D41: =IF(D6<0.05,"n/m",D22/D6) -> 0.081316412 | E41: =IF(E6<0.05,"n/m",E22/E6) -> 0.031411682 | F41: =IF(F6<0.05,"n/m",F22/F6) -> 0.0098125391 | G41: =IF(G6<0.05,"n/m",G22/G6) -> 0.02244482
A42: Standards and regulator affairs | B42: =IF(B6<0.05,"n/m",B23/B6) -> n/m | C42: =IF(C6<0.05,"n/m",C23/C6) -> 0.13967275 | D42: =IF(D6<0.05,"n/m",D23/D6) -> 0.030535143 | E42: =IF(E6<0.05,"n/m",E23/E6) -> 0.011456025 | F42: =IF(F6<0.05,"n/m",F23/F6) -> 0.0049496878 | G42: =IF(G6<0.05,"n/m",G23/G6) -> 0.0089236259
A43: Sales and marketing programmes | B43: =IF(B6<0.05,"n/m",B24/B6) -> n/m | C43: =IF(C6<0.05,"n/m",C24/C6) -> 0.67464472 | D43: =IF(D6<0.05,"n/m",D24/D6) -> 0.25275944 | E43: =IF(E6<0.05,"n/m",E24/E6) -> 0.17612344 | F43: =IF(F6<0.05,"n/m",F24/F6) -> 0.15352746 | G43: =IF(G6<0.05,"n/m",G24/G6) -> 0.16810249
A44: R&D tooling and evaluation | B44: =IF(B6<0.05,"n/m",B25/B6) -> n/m | C44: =IF(C6<0.05,"n/m",C25/C6) -> 0.54403594 | D44: =IF(D6<0.05,"n/m",D25/D6) -> 0.10270761 | E44: =IF(E6<0.05,"n/m",E25/E6) -> 0.033263124 | F44: =IF(F6<0.05,"n/m",F25/F6) -> 0.015048788 | G44: =IF(G6<0.05,"n/m",G25/G6) -> 0.028103086
...

Sheet Headcount
A1: Headcount plan — all ten functions, 54 months
A2: Headcount at the end of every month from October 2026 to March 2031, then the year-end picture with salary bands and the people-cost bridge.
A3: Counts of people. Months run down the rows; functions across the columns. Bands are fully loaded Rs lakh per year at FY2026-27 rates.
A5: Month end | B5: Kernel engineering | C5: Evidence and cryptography | D5: Pack and regulatory engineering | E5: Platform and SRE | F5: Security, compliance, certification | G5: Product and design | H5: Solutions and field engineering | I5: Go to market and partners | J5: Standards, policy, regulator affairs | K5: Finance, legal and operations | L5: Total
A6: Oct 2026 | B6: 4 | C6: 1 | D6: 1 | E6: 2 | F6: 0 | G6: 1 | H6: 0 | I6: 1 | J6: 0 | K6: 1 | L6: =SUM(B6:K6) -> 11
A7: Nov 2026 | B7: 5 | C7: 1 | D7: 1 | E7: 2 | F7: 0 | G7: 1 | H7: 0 | I7: 1 | J7: 0 | K7: 1 | L7: =SUM(B7:K7) -> 12
A8: Dec 2026 | B8: 5 | C8: 2 | D8: 1 | E8: 2 | F8: 1 | G8: 1 | H8: 1 | I8: 2 | J8: 0 | K8: 1 | L8: =SUM(B8:K8) -> 16
A9: Jan 2027 | B9: 6 | C9: 2 | D9: 2 | E9: 3 | F9: 1 | G9: 2 | H9: 1 | I9: 2 | J9: 1 | K9: 2 | L9: =SUM(B9:K9) -> 22
A10: Feb 2027 | B10: 6 | C10: 3 | D10: 2 | E10: 3 | F10: 2 | G10: 2 | H10: 2 | I10: 3 | J10: 1 | K10: 2 | L10: =SUM(B10:K10) -> 26
A11: Mar 2027 | B11: 7 | C11: 3 | D11: 2 | E11: 3 | F11: 2 | G11: 2 | H11: 2 | I11: 3 | J11: 1 | K11: 2 | L11: =SUM(B11:K11) -> 27
A12: Apr 2027 | B12: 8 | C12: 4 | D12: 3 | E12: 4 | F12: 2 | G12: 2 | H12: 3 | I12: 4 | J12: 1 | K12: 2 | L12: =SUM(B12:K12) -> 33
A13: May 2027 | B13: 9 | C13: 4 | D13: 3 | E13: 4 | F13: 3 | G13: 3 | H13: 3 | I13: 5 | J13: 1 | K13: 3 | L13: =SUM(B13:K13) -> 38
A14: Jun 2027 | B14: 10 | C14: 4 | D14: 4 | E14: 4 | F14: 3 | G14: 3 | H14: 4 | I14: 6 | J14: 2 | K14: 4 | L14: =SUM(B14:K14) -> 44
A15: Jul 2027 | B15: 10 | C15: 5 | D15: 5 | E15: 5 | F15: 3 | G15: 3 | H15: 5 | I15: 6 | J15: 2 | K15: 4 | L15: =SUM(B15:K15) -> 48
A16: Aug 2027 | B16: 11 | C16: 6 | D16: 5 | E16: 6 | F16: 4 | G16: 4 | H16: 5 | I16: 7 | J16: 2 | K16: 4 | L16: =SUM(B16:K16) -> 54
A17: Sep 2027 | B17: 12 | C17: 6 | D17: 6 | E17: 6 | F17: 4 | G17: 4 | H17: 6 | I17: 8 | J17: 2 | K17: 5 | L17: =SUM(B17:K17) -> 59
... A59: Mar 2031 | B59: 38 | C59: 26 | D59: 50 | E59: 27 | F59: 21 | G59: 16 | H59: 40 | I59: 50 | J59: 13 | K59: 24 | L59: =SUM(B59:K59) -> 305
A60: Peak headcount | B60: =MAX(B6:B59) -> 38 | C60: =MAX(C6:C59) -> 26 | D60: =MAX(D6:D59) -> 50 | E60: =MAX(E6:E59) -> 27 | F60: =MAX(F6:F59) -> 21 | G60: =MAX(G6:G59) -> 16 | H60: =MAX(H6:H59) -> 40 | I60: =MAX(I6:I59) -> 50 | ... L60: =MAX(L6:L59) -> 305
A62: HEADCOUNT AT END OF FINANCIAL YEAR, WITH SALARY BANDS
A63: Function | B63: Band Rs L/yr | C63: FY2026-27 | D63: FY2027-28 | E63: FY2028-29 | F63: FY2029-30 | G63: FY2030-31
A64: Kernel engineering | B64: 34 | C64: 7 | D64: 17 | E64: 25 | F64: 32 | G64: 38
A65: Evidence and cryptography | B65: 38 | C65: 3 | D65: 9 | E65: 15 | F65: 21 | G65: 26
A66: Pack and regulatory engineering | B66: 30 | C66: 2 | D66: 11 | E66: 23 | F66: 37 | G66: 50
A67: Platform and SRE | B67: 30 | C67: 3 | D67: 9 | E67: 15 | F67: 21 | G67: 27
A68: Security, compliance, certification | B68: 32 | C68: 2 | D68: 6 | E68: 11 | F68: 16 | G68: 21
A69: Product and design | B69: 28 | C69: 2 | D69: 6 | E69: 10 | F69: 13 | G69: 16
A70: Solutions and field engineering | B70: 26 | C70: 2 | D70: 11 | E70: 22 | F70: 32 | G70: 40
A71: Go to market and partners | B71: 27 | C71: 3 | D71: 14 | E71: 28 | F71: 42 | G71: 50
A72: Standards, policy, regulator affairs | B72: 36 | C72: 1 | D72: 4 | E72: 7 | F72: 10 | G72: 13
A73: Finance, legal and operations | B73: 24 | C73: 2 | D73: 8 | E73: 14 | F73: 19 | G73: 24
A74: Total headcount | C74: =SUM(C64:C73) -> 27 | D74: =SUM(D64:D73) -> 95 | E74: =SUM(E64:E73) -> 170 | F74: =SUM(F64:F73) -> 243 | G74: =SUM(G64:G73) -> 305
A75: Net additions in year | C75: =C74 -> 27 | D75: =D74-C74 -> 68 | E75: =E74-D74 -> 75 | F75: =F74-E74 -> 73 | G75: =G74-F74 -> 62
A76: Bands are fully loaded (salary, employer cost, recruitment, equipment) at FY2026-27 rates and escalate 8% per annum thereafter.
A78: PEOPLE COST BRIDGE
A79: Rs crore | B79: FY2026-27 | C79: FY2027-28 | D79: FY2028-29 | E79: FY2029-30 | F79: FY2030-31 | G79: Plan total
A80: People cost in operating expenses | B80: 2.9403753 | C80: 19.737474 | D80: 44.822125 | E80: 74.189567 | F80: 105.6075 | G80: =SUM(B80:F80) -> 247.29705
A81: Delivery and customer success in COGS | B81: 0.073281312 | C81: 1.0224095 | D81: 2.8244313 | E81: 4.9356701 | F81: 7.0574877 | G81: =SUM(B81:F81) -> 15.91328
A82: Total cash people cost | B82: =B80+B81 -> 3.0136566 | C82: =C80+C81 -> 20.759884 | D82: =D80+D81 -> 47.646556 | E82: =E80+E81 -> 79.125237 | F82: =F80+F81 -> 112.66499 | G82: =G80+G81 -> 263.21033
A83: ESOP charge (non-cash) | B83: 0.33150223 | C83: 2.2835872 | D83: 5.2411212 | E83: 8.7037761 | F83: 12.393149 | G83: =SUM(B83:F83) -> 28.953136
A84: ESOP as % of cash people cost | B84: =IFERROR(B83/B82,"n/m") -> 0.11 | C84: =IFERROR(C83/C82,"n/m") -> 0.11 | D84: =IFERROR(D83/D82,"n/m") -> 0.11 | E84: =IFERROR(E83/E82,"n/m") -> 0.11 | F84: =IFERROR(F83/F82,"n/m") -> 0.11 | G84: =IFERROR(G83/G82,"n/m") -> 0.11
...

Sheet Unit economics
A1: Unit economics — the governed action
A2: Volumes, revenue per governed action and cost per governed action by financial year and by quarter, with the external price anchors.
A3: Volumes in millions of governed actions. Rates in Rs per governed action, to three decimals. Margins in per cent.
A5: BY FINANCIAL YEAR
A6: Measure | B6: FY2026-27 | C6: FY2027-28 | D6: FY2028-29 | E6: FY2029-30 | F6: FY2030-31 | G6: Plan total
A7: Governed actions — internal (rung1), millions | B7: 0.36 | C7: 13.04 | D7: 54.6 | E7: 139.5 | F7: 280 | G7: =SUM(B7:F7) -> 487.5
A8: Governed actions — external, millions | B8: 0 | C8: 13.285 | D8: 147.792 | E8: 746.088 | F8: 2211.458 | G8: =SUM(B8:F8) -> 3118.623
A9: Governed actions — total, millions | B9: =B7+B8 -> 0.36 | C9: =C7+C8 -> 26.325 | D9: =D7+D8 -> 202.392 | E9: =E7+E8 -> 885.588 | F9: =F7+F8 -> 2491.458 | G9: =G7+G8 -> 3606.123
A10: Revenue (Rs crore) | B10: 0.0144 | C10: 1.8901325 | D10: 18.077531 | E10: 81.179988 | F10: 230.31755 | G10: =SUM(B10:F10) -> 331.47961
A11: Cost of revenue (Rs crore) | B11: 0.10940403 | C11: 1.6749955 | D11: 6.8355136 | E11: 16.566936 | F11: 32.245312 | G11: =SUM(B11:F11) -> 57.432162
A12: Revenue per governed action (Rs) | B12: =IFERROR(B10*10000000/(B9*1000000),0) -> 0.4 | C12: =IFERROR(C10*10000000/(C9*1000000),0) -> 0.71799904 | D12: =IFERROR(D10*10000000/(D9*1000000),0) -> 0.89319397 | E12: =IFERROR(E10*10000000/(E9*1000000),0) -> 0.91667895 | F12: =IFERROR(F10*10000000/(F9*1000000),0) -> 0.92442881 | G12: =IFERROR(G10*10000000/(G9*1000000),0) -> 0.91921326
A13: Cost per governed action (Rs) | B13: =IFERROR(B11*10000000/(B9*1000000),0) -> 3.039001 | C13: =IFERROR(C11*10000000/(C9*1000000),0) -> 0.6362756 | D13: =IFERROR(D11*10000000/(D9*1000000),0) -> 0.33773636 | E13: =IFERROR(E11*10000000/(E9*1000000),0) -> 0.18707273 | F13: =IFERROR(F11*10000000/(F9*1000000),0) -> 0.12942346 | G13: =IFERROR(G11*10000000/(G9*1000000),0) -> 0.1592629
A14: Contribution per governed action (Rs) | B14: =B12-B13 -> -2.639001 | C14: =C12-C13 -> 0.081723437 | D14: =D12-D13 -> 0.55545762 | E14: =E12-E13 -> 0.72960622 | F14: =F12-F13 -> 0.79500534 | G14: =G12-G13 -> 0.75995035
A15: Gross margin % | B15: =IFERROR((B10-B11)/B10,"n/m") -> -6.5975024 | C15: =IFERROR((C10-C11)/C10,"n/m") -> 0.1138211 | D15: =IFERROR((D10-D11)/D10,"n/m") -> 0.62187793 | E15: =IFERROR((E10-E11)/E10,"n/m") -> 0.79592339 | F15: =IFERROR((F10-F11)/F10,"n/m") -> 0.85999629 | G15: =IFERROR((G10-G11)/G10,"n/m") -> 0.82673998
A16: FY2026-27 revenue per action is the Rs 0.40 internal transfer price only; cost per action that year carries the fixed anchoring and platform floor across 0.36 million actions, so margin is not meaningful.
A18: BY QUARTER — all 18 quarters
A19: Measure | B19: 2026/27 Q3 | C19: 2026/27 Q4 | D19: 2027/28 Q1 | E19: 2027/28 Q2 | F19: 2027/28 Q3 | G19: 2027/28 Q4 | H19: 2028/29 Q1 | I19: 2028/29 Q2 | J19: 2028/29 Q3 | K19: 2028/29 Q4 | L19: 2029/30 Q1 | M19: 2029/30 Q2 | N19: 2029/30 Q3 | O19: 2029/30 Q4 | P19: 2030/31 Q1 | Q19: 2030/31 Q2 | R19: 2030/31 Q3 | S19: 2030/31 Q4 | T19: Plan
A20: Governed actions — internal, millions | B20: 0 | C20: 0.36 | D20: 1.02 | E20: 2.22 | F20: 3.9 | G20: 5.9 | H20: 8.5 | I20: 11.35 | J20: 15.2 | K20: 19.55 | L20: 25 | M20: 31 | N20: 38 | O20: 45.5 | P20: 54.5 | Q20: 64.25 | R20: 75 | S20: 86.25 | T20: =SUM(B20:S20) -> 487.5
A21: Governed actions — external, millions | B21: 0 | C21: 0 | D21: 0 | E21: 1.385 | F21: 3.995 | G21: 7.905 | H21: 16.01 | I21: 26.867 | J21: 42.22 | K21: 62.695 | L21: 90.822 | M21: 152.45 | N21: 214.884 | O21: 287.931 | P21: 373.005 | Q21: 478.435 | R21: 605.508 | S21: 754.51 | T21: =SUM(B21:S21) -> 3118.622
A22: Governed actions — total, millions | B22: =B20+B21 -> 0 | C22: =C20+C21 -> 0.36 | D22: =D20+D21 -> 1.02 | E22: =E20+E21 -> 3.605 | F22: =F20+F21 -> 7.895 | G22: =G20+G21 -> 13.805 | H22: =H20+H21 -> 24.51 | I22: =I20+I21 -> 38.217 | ... T22: =T20+T21 -> 3606.122
A23: Revenue (Rs crore) | B23: 0 | C23: 0.0144 | D23: 0.0408 | E23: 0.22217028 | F23: 0.56226022 | G23: 1.064902 | H23: 2.0478631 | I23: 3.3398867 | J23: 5.1549781 | K23: 7.5348036 | L23: 10.735863 | M23: 16.756142 | N23: 23.114551 | O23: 30.573432 | P23: 39.345087 | Q23: 50.014703 | R23: 62.876635 | S23: 78.08113 | T23: =SUM(B23:S23) -> 331.47961
A24: Cost of revenue (Rs crore) | B24: 0.028570504 | C24: 0.08083353 | D24: 0.14973483 | E24: 0.29014539 | F24: 0.49256854 | G24: 0.74254676 | H24: 1.0916936 | I24: 1.4607987 | J24: 1.8848339 | K24: 2.3981874 | L24: 2.9716191 | M24: 3.7362823 | N24: 4.5302562 | O24: 5.3287789 | P24: 6.2495625 | Q24: 7.3475933 | R24: 8.6058982 | S24: 10.042258 | T24: =SUM(B24:S24) -> 57.432162
A25: Revenue per governed action (Rs) | B25: =IFERROR(B23*10000000/(B22*1000000),0) -> 0 | C25: =IFERROR(C23*10000000/(C22*1000000),0) -> 0.4 | D25: =IFERROR(D23*10000000/(D22*1000000),0) -> 0.4 | E25: =IFERROR(E23*10000000/(E22*1000000),0) -> 0.61628372 | F25: =IFERROR(F23*10000000/(F22*1000000),0) -> 0.71217254 | G25: =IFERROR(G23*10000000/(G22*1000000),0) -> 0.7713886 | H25: =IFERROR(H23*10000000/(H22*1000000),0) -> 0.83552148 | I25: =IFERROR(I23*10000000/(I22*1000000),0) -> 0.87392696 | ... T25: =IFERROR(T23*10000000/(T22*1000000),0) -> 0.91921351
A26: Cost per governed action (Rs) | B26: =IFERROR(B24*10000000/(B22*1000000),0) -> 0 | C26: =IFERROR(C24*10000000/(C22*1000000),0) -> 2.2453758 | D26: =IFERROR(D24*10000000/(D22*1000000),0) -> 1.4679885 | E26: =IFERROR(E24*10000000/(E22*1000000),0) -> 0.80484159 | F26: =IFERROR(F24*10000000/(F22*1000000),0) -> 0.62389935 | G26: =IFERROR(G24*10000000/(G22*1000000),0) -> 0.53788248 | H26: =IFERROR(H24*10000000/(H22*1000000),0) -> 0.44540743 | I26: =IFERROR(I24*10000000/(I22*1000000),0) -> 0.38223793 | ... T26: =IFERROR(T24*10000000/(T22*1000000),0) -> 0.15926295
A27: Gross margin % | B27: =IFERROR((B23-B24)/B23,"n/m") -> n/m | C27: =IFERROR((C23-C24)/C23,"n/m") -> -4.6134396 | D27: =IFERROR((D23-D24)/D23,"n/m") -> -2.6699713 | E27: =IFERROR((E23-E24)/E23,"n/m") -> -0.30595952 | F27: =IFERROR((F23-F24)/F23,"n/m") -> 0.12394916 | G27: =IFERROR((G23-G24)/G23,"n/m") -> 0.30270881 | H27: =IFERROR((H23-H24)/H23,"n/m") -> 0.46691085 | I27: =IFERROR((I23-I24)/I23,"n/m") -> 0.56262028 | ... T27: =IFERROR((T23-T24)/T23,"n/m") -> 0.82673998
A29: PRICE ANCHORS — Rs per governed action
A30: Anchor | B30: Rs per action | C30: US$ per action | D30: Note
A31: Elan1 Govern — internal transfer price to rung1 | B31: 0.4 | C31: =B31/90 -> 0.0044444444 | D31: Cost-plus transfer inside the group; the floor of the price book
A32: Elan1 Govern — L1 Guarded, beyond allowance | B32: 1.6 | C32: =B32/90 -> 0.017777778 | D32: 480,000 actions included per tenant per year
A33: Elan1 Govern — L2 Attested, beyond allowance | B33: 1.2 | C33: =B33/90 -> 0.013333333 | D33: 1,500,000 actions included per tenant per year
A34: Elan1 Govern — L3 Proven, beyond allowance | B34: 0.9 | C34: =B34/90 -> 0.01 | D34: 4,200,000 actions included per tenant per year
A35: Elan1 Govern — sovereign deployment | B35: 0.55 | C35: =B35/90 -> 0.0061111111 | D35: On-premises; the platform floor carries the fixed cost
A36: Salesforce Agentforce | B36: 9 | C36: =B36/90 -> 0.1 | D36: US$0.10 per action (about Rs 8.80 at spot; Rs 9.00 at the workbook's Rs 90.00 rate)
A37: Elan1 Govern blended realised rate, FY2030-31 | B37: =F12 -> 0.92442881 | C37: =B37/90 -> 0.010271431 | D37: Blended across internal and external volume at plan mix
A38: Microsoft Agent 365 is priced at US$15 per user per month. That is a per-seat anchor, not a per-action one, and is not directly comparable to a governed-action rate; it is quoted here only to frame the buyer's alternative.
A39: Elan1 Govern prices governed actions, not seats. Refusals are metered at quantity zero and are never billed, so the buyer pays only for actions that were allowed to complete.

Sheet Cash and funding
A1: Cash and funding — 54-month chain
A2: Opening cash, EBITDA, capex, working capital and funding for every month of the plan. Closing cash is a live formula; the four funding events are highlighted.
A3: Rs crore. Working capital movement is the change in receivables at 55 days DSO on external revenue; a build in receivables is a cash outflow.
A5: Month | B5: Opening cash | C5: EBITDA | D5: Capex | E5: Working capital movement | F5: Funding in | G5: Closing cash | H5: Net burn
A6: Oct 2026 | B6: 0 | C6: -0.47659267 | D6: 0.00952 | E6: 0 | F6: 8 | G6: =B6+C6-D6+E6+F6 -> 7.5138873 | H6: =-C6+D6-E6 -> 0.48611267 | I6: Founder and angel bridge — Rs 8.0 cr
A7: Nov 2026 | B7: =G6 -> 7.5138873 | C7: -0.51125437 | D7: 0.00984 | E7: 0 | F7: 0 | G7: =B7+C7-D7+E7+F7 -> 6.992793 | H7: =-C7+D7-E7 -> 0.52109437
A8: Dec 2026 | B8: =G7 -> 6.992793 | C8: -0.73536624 | D8: 0.01112 | E8: 0 | F8: 0 | G8: =B8+C8-D8+E8+F8 -> 6.2463067 | H8: =-C8+D8-E8 -> 0.74648624
A9: Jan 2027 | B9: =G8 -> 6.2463067 | C9: -0.82075105 | D9: 0.01304 | E9: 0 | F9: 0 | G9: =B9+C9-D9+E9+F9 -> 5.4125157 | H9: =-C9+D9-E9 -> 0.83379105
A10: Feb 2027 | B10: =G9 -> 5.4125157 | C10: -0.95161877 | D10: 0.01432 | E10: 0 | F10: 0 | G10: =B10+C10-D10+E10+F10 -> 4.4465769 | H10: =-C10+D10-E10 -> 0.96593877
A11: Mar 2027 | B11: =G10 -> 4.4465769 | C11: -0.98828944 | D11: 0.01464 | E11: 0 | F11: 63 | G11: =B11+C11-D11+E11+F11 -> 66.443647 | H11: =-C11+D11-E11 -> 1.0029294 | I11: Series A tranche 1 (close, Mar 2027) — Rs 63.0 cr
A12: Apr 2027 | B12: =G11 -> 66.443647 | C12: -1.1829419 | D12: 0.15656 | E12: 0 | F12: 0 | G12: =B12+C12-D12+E12+F12 -> 65.104146 | H12: =-C12+D12-E12 -> 1.3395019
A13: May 2027 | B13: =G12 -> 65.104146 | C13: -1.3410407 | D13: 0.01816 | E13: 0 | F13: 0 | G13: =B13+C13-D13+E13+F13 -> 63.744945 | H13: =-C13+D13-E13 -> 1.3592007
A14: Jun 2027 | B14: =G13 -> 63.744945 | C14: -1.7223382 | D14: 0.02008 | E14: 0 | F14: 0 | G14: =B14+C14-D14+E14+F14 -> 62.002527 | H14: =-C14+D14-E14 -> 1.7424182
A15: Jul 2027 | B15: =G14 -> 62.002527 | C15: -1.6670095 | D15: 0.02136 | E15: -0.039624457 | F15: 0 | G15: =B15+C15-D15+E15+F15 -> 60.274533 | H15: =-C15+D15-E15 -> 1.727994
A16: Aug 2027 | B16: =G15 -> 60.274533 | C16: -1.862387 | D16: 0.02328 | E16: -0.040476391 | F16: 0 | G16: =B16+C16-D16+E16+F16 -> 58.348389 | H16: =-C16+D16-E16 -> 1.9261434
A17: Sep 2027 | B17: =G16 -> 58.348389 | C17: -2.2431193 | D17: 0.02488 | E17: -0.041336546 | F17: 0 | G17: =B17+C17-D17+E17+F17 -> 56.039053 | H17: =-C17+D17-E17 -> 2.3093359
A18: Oct 2027 | B18: =G17 -> 56.039053 | C18: -2.206644 | D18: 0.02648 | E18: -0.061659805 | F18: 0 | G18: =B18+C18-D18+E18+F18 -> 53.74427 | H18: =-C18+D18-E18 -> 2.2947838
A19: Nov 2027 | B19: =G18 -> 53.74427 | C19: -2.4963065 | D19: 0.02936 | E19: -0.060043263 | F19: 0 | G19: =B19+C19-D19+E19+F19 -> 51.15856 | H19: =-C19+D19-E19 -> 2.5857097
A20: Dec 2027 | B20: =G19 -> 51.15856 | C20: -2.8673351 | D20: 0.03032 | E20: -0.0652294 | F20: 0 | G20: =B20+C20-D20+E20+F20 -> 48.195675 | H20: =-C20+D20-E20 -> 2.9628845
A21: Jan 2028 | B21: =G20 -> 48.195675 | C21: -3.0062253 | D21: 0.03192 | E21: -0.093556072 | F21: 0 | G21: =B21+C21-D21+E21+F21 -> 45.063974 | H21: =-C21+D21-E21 -> 3.1317014
A22: Feb 2028 | B22: =G21 -> 45.063974 | C22: -2.9720448 | D22: 0.03448 | E22: -0.097786774 | F22: 0 | G22: =B22+C22-D22+E22+F22 -> 41.959662 | H22: =-C22+D22-E22 -> 3.1043116
A23: Mar 2028 | B23: =G22 -> 41.959662 | C23: -3.159011 | D23: 0.0364 | E23: -0.097485068 | F23: 0 | G23: =B23+C23-D23+E23+F23 -> 38.666766 | H23: =-C23+D23-E23 -> 3.292896
... A29: Sep 2028 | B29: =G28 -> 18.457982 | C29: -4.0019215 | D29: 0.04824 | E29: -0.27572453 | F29: 0 | G29: =B29+C29-D29+E29+F29 -> 14.132096 | H29: =-C29+D29-E29 -> 4.325886
A30: Oct 2028 | B30: =G29 -> 14.132096 | C30: -4.6835942 | D30: 0.05016 | E30: -0.34597661 | F30: 72 | G30: =B30+C30-D30+E30+F30 -> 81.052365 | H30: =-C30+D30-E30 -> 5.0797308 | I30: Series A tranche 2 (Gate A, Oct 2028) — Rs 72.0 cr
A31: Nov 2028 | B31: =G30 -> 81.052365 | C31: -4.3477123 | D31: 0.05208 | E31: -0.36913878 | F31: 0 | G31: =B31+C31-D31+E31+F31 -> 76.283434 | H31: =-C31+D31-E31 -> 4.768931
A32: Dec 2028 | B32: =G31 -> 76.283434 | C32: -4.4671088 | D32: 0.05432 | E32: -0.39477796 | F32: 0 | G32: =B32+C32-D32+E32+F32 -> 71.367227 | H32: =-C32+D32-E32 -> 4.9162067
A33: Jan 2029 | B33: =G32 -> 71.367227 | C33: -5.2838191 | D33: 0.05624 | E33: -0.44424927 | F33: 0 | G33: =B33+C33-D33+E33+F33 -> 65.582919 | H33: =-C33+D33-E33 -> 5.7843084
A34: Feb 2029 | B34: =G33 -> 65.582919 | C34: -4.5938847 | D34: 0.05848 | E34: -0.4996485 | F34: 0 | G34: =B34+C34-D34+E34+F34 -> 60.430906 | H34: =-C34+D34-E34 -> 5.1520132
A35: Mar 2029 | B35: =G34 -> 60.430906 | C35: -4.6428034 | D35: 0.0604 | E35: -0.49787638 | F35: 0 | G35: =B35+C35-D35+E35+F35 -> 55.229826 | H35: =-C35+D35-E35 -> 5.2010798
A36: Apr 2029 | B36: =G35 -> 55.229826 | C36: -5.1387535 | D36: 0.20232 | E36: -0.59155892 | F36: 0 | G36: =B36+C36-D36+E36+F36 -> 49.297193 | H36: =-C36+D36-E36 -> 5.9326324
A37: May 2029 | B37: =G36 -> 49.297193 | C37: -4.615336 | D37: 0.06424 | E37: -0.68129691 | F37: 0 | G37: =B37+C37-D37+E37+F37 -> 43.936321 | H37: =-C37+D37-E37 -> 5.3608729
A38: Jun 2029 | B38: =G37 -> 43.936321 | C38: -4.5217424 | D38: 0.06584 | E38: -0.76135307 | F38: 0 | G38: =B38+C38-D38+E38+F38 -> 38.587385 | H38: =-C38+D38-E38 -> 5.3489355
A39: Jul 2029 | B39: =G38 -> 38.587385 | C39: -5.1672947 | D39: 0.0684 | E39: -1.4272539 | F39: 45 | G39: =B39+C39-D39+E39+F39 -> 76.924436 | H39: =-C39+D39-E39 -> 6.6629486 | I39: Series A tranche 3 (Gate B, Jul 2029) — Rs 45.0 cr
A40: Aug 2029 | B40: =G39 -> 76.924436 | C40: -4.0368766 | D40: 0.07032 | E40: -1.5227914 | F40: 0 | G40: =B40+C40-D40+E40+F40 -> 71.294448 | H40: =-C40+D40-E40 -> 5.629988
A41: Sep 2029 | B41: =G40 -> 71.294448 | C41: -3.8683712 | D41: 0.07192 | E41: -0.92066464 | F41: 0 | G41: =B41+C41-D41+E41+F41 -> 66.433493 | H41: =-C41+D41-E41 -> 4.8609559
A42: Oct 2029 | B42: =G41 -> 66.433493 | C42: -4.3341625 | D42: 0.07384 | E42: -1.0214647 | F42: 0 | G42: =B42+C42-D42+E42+F42 -> 61.004025 | H42: =-C42+D42-E42 -> 5.4294672
A43: Nov 2029 | B43: =G42 -> 61.004025 | C43: -3.3341515 | D43: 0.07576 | E43: -1.7102325 | F43: 0 | G43: =B43+C43-D43+E43+F43 -> 55.883881 | H43: =-C43+D43-E43 -> 5.120144
A44: Dec 2029 | B44: =G43 -> 55.883881 | C44: -3.1859574 | D44: 0.07832 | E44: -1.1421148 | F44: 0 | G44: =B44+C44-D44+E44+F44 -> 51.477489 | H44: =-C44+D44-E44 -> 4.4063922
A45: Jan 2030 | B45: =G44 -> 51.477489 | C45: -3.8842952 | D45: 0.07992 | E45: -1.250105 | F45: 0 | G45: =B45+C45-D45+E45+F45 -> 46.263169 | H45: =-C45+D45-E45 -> 5.2143202
